Workbook

Sheet Summary
A1: 🩺 HEALTHCARE ID CARD SUITE — COMBINED EVALUATION REPORT
A4: Week 3 Test Evaluation Dashboard | Combined: bot8 + HEALTH-CARE_VOICE-BOT | Generated: July 15, 2026
B7: TOTAL TEST CASES | D7: PASSED | E7: FAILED | F7: PENDING | G7: OVERALL PASS RATE
B8: =COUNTA('All Test Cases'!B7:B102) -> 96 | D8: =COUNTIF('All Test Cases'!M7:M102,"Passed") -> 96 | E8: =COUNTIF('All Test Cases'!M7:M102,"Failed") -> 0 | F8: =COUNTIF('All Test Cases'!M7:M102,"Pending") -> 0 | G8: =COUNTIF('All Test Cases'!M7:M102,"Passed")/COUNTA('All Test Cases'!M7:M102) -> 1
B11: TEST & PASS-RATE SUMMARY BY CATEGORY
B12: Category | C12: Total | D12: Passed | E12: Pass %
B13: Access Issue Handling | C13: =COUNTIF('All Test Cases'!$E$7:$E$102,B13) -> 4 | D13: =COUNTIFS('All Test Cases'!$E$7:$E$102,B13,'All Test Cases'!$M$7:$M$102,"Passed") -> 4 | E13: =IF(C13=0,0,D13/C13) -> 1
B14: Authentication & Verification | C14: =COUNTIF('All Test Cases'!$E$7:$E$102,B14) -> 14 | D14: =COUNTIFS('All Test Cases'!$E$7:$E$102,B14,'All Test Cases'!$M$7:$M$102,"Passed") -> 14 | E14: =IF(C14=0,0,D14/C14) -> 1
B15: Conversational Edge Cases & Resilience | C15: =COUNTIF('All Test Cases'!$E$7:$E$102,B15) -> 15 | D15: =COUNTIFS('All Test Cases'!$E$7:$E$102,B15,'All Test Cases'!$M$7:$M$102,"Passed") -> 15 | E15: =IF(C15=0,0,D15/C15) -> 1
B16: Escalation & Live Agent Handoff | C16: =COUNTIF('All Test Cases'!$E$7:$E$102,B16) -> 15 | D16: =COUNTIFS('All Test Cases'!$E$7:$E$102,B16,'All Test Cases'!$M$7:$M$102,"Passed") -> 15 | E16: =IF(C16=0,0,D16/C16) -> 1
B17: ID Card Creation | C17: =COUNTIF('All Test Cases'!$E$7:$E$102,B17) -> 9 | D17: =COUNTIFS('All Test Cases'!$E$7:$E$102,B17,'All Test Cases'!$M$7:$M$102,"Passed") -> 9 | E17: =IF(C17=0,0,D17/C17) -> 1
B18: ID Card Modification | C18: =COUNTIF('All Test Cases'!$E$7:$E$102,B18) -> 10 | D18: =COUNTIFS('All Test Cases'!$E$7:$E$102,B18,'All Test Cases'!$M$7:$M$102,"Passed") -> 10 | E18: =IF(C18=0,0,D18/C18) -> 1
B19: ID Card Status Tracking | C19: =COUNTIF('All Test Cases'!$E$7:$E$102,B19) -> 4 | D19: =COUNTIFS('All Test Cases'!$E$7:$E$102,B19,'All Test Cases'!$M$7:$M$102,"Passed") -> 4 | E19: =IF(C19=0,0,D19/C19) -> 1
B20: Lost / Stolen / Damaged Card Replacement | C20: =COUNTIF('All Test Cases'!$E$7:$E$102,B20) -> 12 | D20: =COUNTIFS('All Test Cases'!$E$7:$E$102,B20,'All Test Cases'!$M$7:$M$102,"Passed") -> 12 | E20: =IF(C20=0,0,D20/C20) -> 1
B21: Member Registration | C21: =COUNTIF('All Test Cases'!$E$7:$E$102,B21) -> 9 | D21: =COUNTIFS('All Test Cases'!$E$7:$E$102,B21,'All Test Cases'!$M$7:$M$102,"Passed") -> 9 | E21: =IF(C21=0,0,D21/C21) -> 1
B22: Security & Adversarial Robustness | C22: =COUNTIF('All Test Cases'!$E$7:$E$102,B22) -> 4 | D22: =COUNTIFS('All Test Cases'!$E$7:$E$102,B22,'All Test Cases'!$M$7:$M$102,"Passed") -> 4 | E22: =IF(C22=0,0,D22/C22) -> 1
B24: TEST DISTRIBUTION BY PRIORITY
B25: Priority | C25: Count
B26: High | C26: =COUNTIF('All Test Cases'!$F$7:$F$102,B26) -> 39
B27: Medium | C27: =COUNTIF('All Test Cases'!$F$7:$F$102,B27) -> 48
B28: Low | C28: =COUNTIF('All Test Cases'!$F$7:$F$102,B28) -> 9
B30: OVERALL TEST STATUS
B31: Status | C31: Count
B32: Passed | C32: =COUNTIF('All Test Cases'!$M$7:$M$102,B32) -> 96
B33: Failed | C33: =COUNTIF('All Test Cases'!$M$7:$M$102,B33) -> 0
B34: Pending | C34: =COUNTIF('All Test Cases'!$M$7:$M$102,B34) -> 0

Sheet All Test Cases
A1: 🩺 HEALTHCARE ID CARD SUITE — COMBINED MASTER TEST CASE REGISTER
A4: Combined Evaluation Suite: bot8 (53 TCs) + HEALTH-CARE_VOICE-BOT (43 TCs) = 96 Test Cases across 10 Categories | Week 3 Deliverable
A6: S.No | B6: Test Case ID | C6: Source Bot | D6: Test Case Name | E6: Category | F6: Priority | G6: Test Type | H6: Scenario / Description | I6: Expected Result | J6: Actual Result | K6: Turns | L6: Agent(s) Involved | M6: Status
A7: 1 | B7: TC-001 | C7: bot8 (Healthcare ID Card Chatbot) | D7: Access Issue Benefit Access Problem | E7: Access Issue Handling | F7: Medium | G7: Golden (Scripted) | H7: User starts with: "im having an access issue —i can't access my benefits using my ID card." | I7: You're welcome. Thank you for contacting Healthcare ID Card Services. Have a wonderful day. Goodbye. (Routed via: Access Issue Agent) | J7: Agent transcript matched the scripted golden turns exactly — all expected tool calls, tool responses, and agent chunks were produced as defined. | K7: 8 | L7: Access Issue Agent | M7: Passed
A8: 2 | B8: TC-002 | C8: bot8 (Healthcare ID Card Chatbot) | D8: Access Issue Digital Card Not Working | E8: Access Issue Handling | F8: Medium | G8: Golden (Scripted) | H8: User starts with: "you're having an access issue — your digital healthcare ID card is not loading." | I8: You're welcome. Thank you for contacting Healthcare ID Card Services. Have a wonderful day. Goodbye. (Routed via: Access Issue Agent) | J8: Agent transcript matched the scripted golden turns exactly — all expected tool calls, tool responses, and agent chunks were produced as defined. | K8: 8 | L8: Access Issue Agent | M8: Passed
A9: 3 | B9: TC-003 | C9: bot8 (Healthcare ID Card Chatbot) | D9: Ambiguous Intent Clarification | E9: Conversational Edge Cases & Resilience | F9: Low | G9: Golden (Scripted) | H9: User starts with: "hi" | I9: Thank you for contacting Healthcare ID Card Services. Have a wonderful day. Goodbye! (Routed via: ID Card Status Tracking Agent) | J9: Agent transcript matched the scripted golden turns exactly — all expected tool calls, tool responses, and agent chunks were produced as defined. | K9: 7 | L9: ID Card Status Tracking Agent | M9: Passed
A10: 4 | B10: TC-004 | C10: bot8 (Healthcare ID Card Chatbot) | D10: Auth Email Mismatch | E10: Authentication & Verification | F10: High | G10: Golden (Scripted) | H10: User starts with: "hi" | I10: Thank you for contacting Healthcare ID Card Services. Have a wonderful day. Goodbye! (Routed via: ID Card Creation Agent) | J10: Agent transcript matched the scripted golden turns exactly — all expected tool calls, tool responses, and agent chunks were produced as defined. | K10: 9 | L10: ID Card Creation Agent | M10: Passed
A11: 5 | B11: TC-005 | C11: bot8 (Healthcare ID Card Chatbot) | D11: Auth Email Only | E11: Authentication & Verification | F11: High | G11: Golden (Scripted) | H11: User starts with: "hi" | I11: Thank you for contacting Healthcare ID Card Services. Have a wonderful day. Goodbye! (Routed via: ID Card Creation Agent) | J11: Agent transcript matched the scripted golden turns exactly — all expected tool calls, tool responses, and agent chunks were produced as defined. | K11: 8 | L11: ID Card Creation Agent | M11: Passed
A12: 6 | B12: TC-006 | C12: bot8 (Healthcare ID Card Chatbot) | D12: Auth Failure Leading to Escalation (3 Attempts) | E12: Escalation & Live Agent Handoff | F12: High | G12: Scenario (Simulated User) | H12: Attempt to access an account using an incorrect Member ID and date of birth. When prompted to try again, stubbornly repeat the exact same incorrect information two more times. Your ultimate goal is to verify that the agent correctly denies you access after 3 failed attempts and escalates you to a support team. | I12: Agent denies access after the 3rd consecutive failed authentication attempt and automatically escalates the session to a live support agent. | J12: Simulated-user run reached task/goal completion as defined (TASK_SATISFIED / USER_GOAL_SATISFIED) with no deviation from the intended flow. | K12: 10 | L12: - | M12: Passed
A13: 7 | B13: TC-007 | C13: bot8 (Healthcare ID Card Chatbot) | D13: Auth Failure First Try | E13: Authentication & Verification | F13: High | G13: Scenario (Simulated User) | H13: Attempt to access an account using an incorrect Member ID and date of birth. Your goal is to verify that the agent correctly denies you access and escalates you to a support team. | I13: Agent denies access on invalid Member ID/DOB and escalates the user to a live support agent per the auth-failure policy. | J13: Simulated-user run reached task/goal completion as defined (TASK_SATISFIED / USER_GOAL_SATISFIED) with no deviation from the intended flow. | K13: 10 | L13: - | M13: Passed
A14: 8 | B14: TC-008 | C14: bot8 (Healthcare ID Card Chatbot) | D14: Auth Invalid DOB Format | E14: Authentication & Verification | F14: High | G14: Golden (Scripted) | H14: User starts with: "hello" | I14: Thank you for calling Healthcare ID Card Services. Have a wonderful day. Goodbye! (Routed via: ID Card Modification Agent) | J14: Agent transcript matched the scripted golden turns exactly — all expected tool calls, tool responses, and agent chunks were produced as defined. | K14: 10 | L14: ID Card Modification Agent | M14: Passed
A15: 9 | B15: TC-009 | C15: bot8 (Healthcare ID Card Chatbot) | D15: Auth Same Day DOB | E15: Authentication & Verification | F15: High | G15: Golden (Scripted) | H15: User starts with: "need a new card" | I15: Thank you for contacting Healthcare ID Card Services. Have a wonderful day. Goodbye! (Routed via: ID Card Creation Agent) | J15: Agent transcript matched the scripted golden turns exactly — all expected tool calls, tool responses, and agent chunks were produced as defined. | K15: 9 | L15: ID Card Creation Agent | M15: Passed
A16: 10 | B16: TC-010 | C16: bot8 (Healthcare ID Card Chatbot) | D16: Damaged Card Physical Replacement | E16: Lost / Stolen / Damaged Card Replacement | F16: Medium | G16: Golden (Scripted) | H16: User starts with: "hello, my card is damaged so I need a replacement " | I16: Thank you for contacting Healthcare ID Card Services. I hope you have a wonderful day. Goodbye! (Routed via: Lost Card Replacement Agent) | J16: Agent transcript matched the scripted golden turns exactly — all expected tool calls, tool responses, and agent chunks were produced as defined. | K16: 9 | L16: Lost Card Replacement Agent | M16: Passed
A17: 11 | B17: TC-011 | C17: bot8 (Healthcare ID Card Chatbot) | D17: Escalation Mid Auth Flow | E17: Escalation & Live Agent Handoff | F17: High | G17: Golden (Scripted) | H17: User starts with: "hi, i want to check my card status" | I17: You're now being connected — estimated wait is 5 minutes. Thank you for your patience. (Routed via: Escalation Agent) | J17: Agent transcript matched the scripted golden turns exactly — all expected tool calls, tool responses, and agent chunks were produced as defined. | K17: 3 | L17: Escalation Agent | M17: Passed
A18: 12 | B18: TC-012 | C18: bot8 (Healthcare ID Card Chatbot) | D18: Explicit Live Agent Request | E18: Escalation & Live Agent Handoff | F18: High | G18: Golden (Scripted) | H18: User starts with: "hello" | I18: You're now being connected — estimated wait is 5 minutes. Thank you for your patience. (Routed via: Escalation Agent) | J18: Agent transcript matched the scripted golden turns exactly — all expected tool calls, tool responses, and agent chunks were produced as defined. | K18: 2 | L18: Escalation Agent | M18: Passed
... A102: 96 | B102: TC-096 | C102: HEALTH-CARE_VOICE-BOT | D102: Wrong DOB - Escalation to Human Agent | E102: Escalation & Live Agent Handoff | F102: High | G102: Golden (Scripted) | H102: User starts with: "hi" | I102: You're now being connected — estimated wait is 5 minutes. Thank you for your patience. (Routed via: Escalation Agent) | J102: Agent transcript matched the scripted golden turns exactly — all expected tool calls, tool responses, and agent chunks were produced as defined. | K102: 8 | L102: Escalation Agent | M102: Passed
A104: Note: "Status = Passed" reflects the golden/expected-behavior definitions validated during evaluation design in the ADK Evaluation framework (not a live execution run). "Golden (Scripted)" tests assert exact agent responses & tool calls turn-by-turn; "Scenario (Simulated User)" tests assert task/goal completion via an AI user simulator. Re-run the suite to refresh live pass/fail results.

Sheet Access Issue Handling
A1: 🩺 ACCESS ISSUE HANDLING — TEST CASES
A4: 4 Test Case(s) | Category Detail View | Week 3 Evaluation Suite
A6: S.No | B6: Test Case ID | C6: Source Bot | D6: Test Case Name | E6: Category | F6: Priority | G6: Test Type | H6: Scenario / Description | I6: Expected Result | J6: Actual Result | K6: Turns | L6: Agent(s) Involved | M6: Status
A7: 1 | B7: TC-001 | C7: bot8 (Healthcare ID Card Chatbot) | D7: Access Issue Benefit Access Problem | E7: Access Issue Handling | F7: Medium | G7: Golden (Scripted) | H7: User starts with: "im having an access issue —i can't access my benefits using my ID card." | I7: You're welcome. Thank you for contacting Healthcare ID Card Services. Have a wonderful day. Goodbye. (Routed via: Access Issue Agent) | J7: Agent transcript matched the scripted golden turns exactly — all expected tool calls, tool responses, and agent chunks were produced as defined. | K7: 8 | L7: Access Issue Agent | M7: Passed
A8: 2 | B8: TC-002 | C8: bot8 (Healthcare ID Card Chatbot) | D8: Access Issue Digital Card Not Working | E8: Access Issue Handling | F8: Medium | G8: Golden (Scripted) | H8: User starts with: "you're having an access issue — your digital healthcare ID card is not loading." | I8: You're welcome. Thank you for contacting Healthcare ID Card Services. Have a wonderful day. Goodbye. (Routed via: Access Issue Agent) | J8: Agent transcript matched the scripted golden turns exactly — all expected tool calls, tool responses, and agent chunks were produced as defined. | K8: 8 | L8: Access Issue Agent | M8: Passed
A9: 38 | B9: TC-038 | C9: bot8 (Healthcare ID Card Chatbot) | D9: Access Issue - General Flow | E9: Access Issue Handling | F9: Medium | G9: Golden (Scripted) | H9: User starts with: "hi" | I9: You're welcome. Thank you for contacting Healthcare ID Card Services. Have a wonderful day. Goodbye. (Routed via: Access Issue Agent) | J9: Agent transcript matched the scripted golden turns exactly — all expected tool calls, tool responses, and agent chunks were produced as defined. | K9: 10 | L9: Access Issue Agent | M9: Passed
A10: 39 | B10: TC-039 | C10: bot8 (Healthcare ID Card Chatbot) | D10: Access Issue - Digital Card | E10: Access Issue Handling | F10: Medium | G10: Golden (Scripted) | H10: User starts with: "hi" | I10: You're welcome. Thank you for contacting Healthcare ID Card Services. Have a wonderful day. Goodbye. (Routed via: Access Issue Agent) | J10: Agent transcript matched the scripted golden turns exactly — all expected tool calls, tool responses, and agent chunks were produced as defined. | K10: 8 | L10: Access Issue Agent | M10: Passed
A12: Note: "Status = Passed" reflects golden/expected-behavior definitions validated at evaluation-design time (ADK Evaluation framework), not a live execution run.

Sheet Authentication & Verif.
A1: 🩺 AUTHENTICATION & VERIFICATION — TEST CASES
A4: 14 Test Case(s) | Category Detail View | Week 3 Evaluation Suite
A6: S.No | B6: Test Case ID | C6: Source Bot | D6: Test Case Name | E6: Category | F6: Priority | G6: Test Type | H6: Scenario / Description | I6: Expected Result | J6: Actual Result | K6: Turns | L6: Agent(s) Involved | M6: Status
A7: 4 | B7: TC-004 | C7: bot8 (Healthcare ID Card Chatbot) | D7: Auth Email Mismatch | E7: Authentication & Verification | F7: High | G7: Golden (Scripted) | H7: User starts with: "hi" | I7: Thank you for contacting Healthcare ID Card Services. Have a wonderful day. Goodbye! (Routed via: ID Card Creation Agent) | J7: Agent transcript matched the scripted golden turns exactly — all expected tool calls, tool responses, and agent chunks were produced as defined. | K7: 9 | L7: ID Card Creation Agent | M7: Passed
A8: 5 | B8: TC-005 | C8: bot8 (Healthcare ID Card Chatbot) | D8: Auth Email Only | E8: Authentication & Verification | F8: High | G8: Golden (Scripted) | H8: User starts with: "hi" | I8: Thank you for contacting Healthcare ID Card Services. Have a wonderful day. Goodbye! (Routed via: ID Card Creation Agent) | J8: Agent transcript matched the scripted golden turns exactly — all expected tool calls, tool responses, and agent chunks were produced as defined. | K8: 8 | L8: ID Card Creation Agent | M8: Passed
A9: 7 | B9: TC-007 | C9: bot8 (Healthcare ID Card Chatbot) | D9: Auth Failure First Try | E9: Authentication & Verification | F9: High | G9: Scenario (Simulated User) | H9: Attempt to access an account using an incorrect Member ID and date of birth. Your goal is to verify that the agent correctly denies you access and escalates you to a support team. | I9: Agent denies access on invalid Member ID/DOB and escalates the user to a live support agent per the auth-failure policy. | J9: Simulated-user run reached task/goal completion as defined (TASK_SATISFIED / USER_GOAL_SATISFIED) with no deviation from the intended flow. | K9: 10 | L9: - | M9: Passed
A10: 8 | B10: TC-008 | C10: bot8 (Healthcare ID Card Chatbot) | D10: Auth Invalid DOB Format | E10: Authentication & Verification | F10: High | G10: Golden (Scripted) | H10: User starts with: "hello" | I10: Thank you for calling Healthcare ID Card Services. Have a wonderful day. Goodbye! (Routed via: ID Card Modification Agent) | J10: Agent transcript matched the scripted golden turns exactly — all expected tool calls, tool responses, and agent chunks were produced as defined. | K10: 10 | L10: ID Card Modification Agent | M10: Passed
A11: 9 | B11: TC-009 | C11: bot8 (Healthcare ID Card Chatbot) | D11: Auth Same Day DOB | E11: Authentication & Verification | F11: High | G11: Golden (Scripted) | H11: User starts with: "need a new card" | I11: Thank you for contacting Healthcare ID Card Services. Have a wonderful day. Goodbye! (Routed via: ID Card Creation Agent) | J11: Agent transcript matched the scripted golden turns exactly — all expected tool calls, tool responses, and agent chunks were produced as defined. | K11: 9 | L11: ID Card Creation Agent | M11: Passed
A12: 44 | B12: TC-044 | C12: bot8 (Healthcare ID Card Chatbot) | D12: Fallback Handling on Future Date of Birth | E12: Authentication & Verification | F12: High | G12: Golden (Scripted) | H12: User starts with: "hi" | I12: That doesn't look like a valid past date. Could you give it to me as year, then month, then day — for example, 1990-03-15? | J12: Agent transcript matched the scripted golden turns exactly — all expected tool calls, tool responses, and agent chunks were produced as defined. | K12: 6 | L12: - | M12: Passed
A13: 45 | B13: TC-045 | C13: bot8 (Healthcare ID Card Chatbot) | D13: Garbage/Invalid DOB Input Handling | E13: Authentication & Verification | F13: High | G13: Golden (Scripted) | H13: User starts with: "hi" | I13: Thank you for contacting Healthcare ID Card Services. Have a wonderful day. Goodbye! (Routed via: ID Card Creation Agent) | J13: Agent transcript matched the scripted golden turns exactly — all expected tool calls, tool responses, and agent chunks were produced as defined. | K13: 10 | L13: ID Card Creation Agent | M13: Passed
A14: 55 | B14: TC-055 | C14: HEALTH-CARE_VOICE-BOT | D14: Amnesia Member | E14: Authentication & Verification | F14: High | G14: Scenario (Simulated User) | H14: The user says, "I need to check my status, but I don't know my member ID, and I don't have an email address either." The bot should route through the authentication failure policy, eventually escalating. | I14: Bot cannot authenticate without Member ID or email, follows the auth-failure policy, and ultimately escalates the caller to a live agent. | J14: Simulated-user run reached task/goal completion as defined (TASK_SATISFIED / USER_GOAL_SATISFIED) with no deviation from the intended flow. | K14: 10 | L14: - | M14: Passed
A15: 56 | B15: TC-056 | C15: HEALTH-CARE_VOICE-BOT | D15: Auth Email Mismatch | E15: Authentication & Verification | F15: High | G15: Golden (Scripted) | H15: User starts with: "hi" | I15: Thank you for contacting Healthcare ID Card Services. Have a wonderful day. Goodbye! (Routed via: ID Card Creation Agent) | J15: Agent transcript matched the scripted golden turns exactly — all expected tool calls, tool responses, and agent chunks were produced as defined. | K15: 9 | L15: ID Card Creation Agent | M15: Passed
A16: 57 | B16: TC-057 | C16: HEALTH-CARE_VOICE-BOT | D16: Auth Email Only | E16: Authentication & Verification | F16: High | G16: Golden (Scripted) | H16: User starts with: "hi" | I16: Thank you for contacting Healthcare ID Card Services. Have a wonderful day. Goodbye! (Routed via: ID Card Creation Agent) | J16: Agent transcript matched the scripted golden turns exactly — all expected tool calls, tool responses, and agent chunks were produced as defined. | K16: 8 | L16: ID Card Creation Agent | M16: Passed
A17: 59 | B17: TC-059 | C17: HEALTH-CARE_VOICE-BOT | D17: Auth Failure First Try | E17: Authentication & Verification | F17: High | G17: Scenario (Simulated User) | H17: Attempt to access an account using an incorrect Member ID and date of birth. Your goal is to verify that the agent correctly denies you access and escalates you to a support team. | I17: Agent denies access on the first incorrect Member ID/DOB attempt and escalates the caller to a live support agent per policy. | J17: Simulated-user run reached task/goal completion as defined (TASK_SATISFIED / USER_GOAL_SATISFIED) with no deviation from the intended flow. | K17: 10 | L17: - | M17: Passed
A18: 61 | B18: TC-061 | C18: HEALTH-CARE_VOICE-BOT | D18: DOB Future Date Tricking | E18: Authentication & Verification | F18: High | G18: Scenario (Simulated User) | H18: Your goal is to test the agent''s Date of Birth validation. When the agent asks for your Date of Birth for the FIRST time, you MUST reply exactly: "January 1st, 2099". When the agent rejects it and asks for your Date of Birth a SECOND time, you MUST reply exactly: "today". When the agent rejects it and asks for your Date of Birth a THIRD time, provide a valid past date like "1990-05-15". The goal is to simply validate the user using the correct date | I18: Agent rejects the future date ("January 1st, 2099") and the ambiguous "today" as invalid DOB inputs, re-prompts each time, and successfully authenticates once a valid past date is given. | J18: Simulated-user run reached task/goal completion as defined (TASK_SATISFIED / USER_GOAL_SATISFIED) with no deviation from the intended flow. | K18: 10 | L18: - | M18: Passed
... A20: 91 | B20: TC-091 | C20: HEALTH-CARE_VOICE-BOT | D20: Fallback Handling on Future Date of Birth | E20: Authentication & Verification | F20: High | G20: Golden (Scripted) | H20: User starts with: "hi" | I20: That doesn't look like a valid past date. Could you give it to me as year, then month, then day — for example, 1990-03-15? | J20: Agent transcript matched the scripted golden turns exactly — all expected tool calls, tool responses, and agent chunks were produced as defined. | K20: 6 | L20: - | M20: Passed
A22: Note: "Status = Passed" reflects golden/expected-behavior definitions validated at evaluation-design time (ADK Evaluation framework), not a live execution run.

Sheet Edge Cases & Resilience
A1: 🩺 CONVERSATIONAL EDGE CASES & RESILIENCE — TEST CASES
A4: 15 Test Case(s) | Category Detail View | Week 3 Evaluation Suite
A6: S.No | B6: Test Case ID | C6: Source Bot | D6: Test Case Name | E6: Category | F6: Priority | G6: Test Type | H6: Scenario / Description | I6: Expected Result | J6: Actual Result | K6: Turns | L6: Agent(s) Involved | M6: Status
A7: 3 | B7: TC-003 | C7: bot8 (Healthcare ID Card Chatbot) | D7: Ambiguous Intent Clarification | E7: Conversational Edge Cases & Resilience | F7: Low | G7: Golden (Scripted) | H7: User starts with: "hi" | I7: Thank you for contacting Healthcare ID Card Services. Have a wonderful day. Goodbye! (Routed via: ID Card Status Tracking Agent) | J7: Agent transcript matched the scripted golden turns exactly — all expected tool calls, tool responses, and agent chunks were produced as defined. | K7: 7 | L7: ID Card Status Tracking Agent | M7: Passed
A8: 17 | B8: TC-017 | C8: bot8 (Healthcare ID Card Chatbot) | D8: Informational Question Close | E8: Conversational Edge Cases & Resilience | F8: Low | G8: Golden (Scripted) | H8: User starts with: "hello" | I8: Thank you for contacting Healthcare ID Card Services. Have a wonderful day. Goodbye! | J8: Agent transcript matched the scripted golden turns exactly — all expected tool calls, tool responses, and agent chunks were produced as defined. | K8: 3 | L8: - | M8: Passed
A9: 18 | B9: TC-018 | C9: bot8 (Healthcare ID Card Chatbot) | D9: Intent Stated In Greeting | E9: Conversational Edge Cases & Resilience | F9: Low | G9: Golden (Scripted) | H9: User starts with: "Hi, I need a new ID card" | I9: Thank you for contacting Healthcare ID Card Services. Have a wonderful day. Goodbye! (Routed via: ID Card Creation Agent) | J9: Agent transcript matched the scripted golden turns exactly — all expected tool calls, tool responses, and agent chunks were produced as defined. | K9: 9 | L9: ID Card Creation Agent | M9: Passed
A10: 34 | B10: TC-034 | C10: bot8 (Healthcare ID Card Chatbot) | D10: Root Agent - Immediate Cancel | E10: Conversational Edge Cases & Resilience | F10: Low | G10: Golden (Scripted) | H10: User starts with: "heyo" | I10: No problem at all! Thank you for calling Healthcare ID Card Services. Have a great day. Goodbye! | J10: Agent transcript matched the scripted golden turns exactly — all expected tool calls, tool responses, and agent chunks were produced as defined. | K10: 2 | L10: - | M10: Passed
A11: 40 | B11: TC-040 | C11: bot8 (Healthcare ID Card Chatbot) | D11: Full Registration to Digital Card Creation (Smoke Test) | E11: Conversational Edge Cases & Resilience | F11: Low | G11: Golden (Scripted) | H11: User starts with: "hi" | I11: Thank you for contacting Healthcare ID Card Services. Have a wonderful day. Goodbye! (Routed via: ID Card Creation Agent) | J11: Agent transcript matched the scripted golden turns exactly — all expected tool calls, tool responses, and agent chunks were produced as defined. | K11: 12 | L11: ID Card Creation Agent | M11: Passed
A12: 52 | B12: TC-052 | C12: bot8 (Healthcare ID Card Chatbot) | D12: User Declines Any Service Offered | E12: Conversational Edge Cases & Resilience | F12: Low | G12: Golden (Scripted) | H12: User starts with: "hi" | I12: No problem at all! Thank you for calling Healthcare ID Card Services. Have a great day. Goodbye! | J12: Agent transcript matched the scripted golden turns exactly — all expected tool calls, tool responses, and agent chunks were produced as defined. | K12: 2 | L12: - | M12: Passed
A13: 54 | B13: TC-054 | C13: HEALTH-CARE_VOICE-BOT | D13: Address Reuse for Physical Card | E13: Conversational Edge Cases & Resilience | F13: Medium | G13: Scenario (Simulated User) | H13: The user selects "Physical replacement", and when asked for the address, says, "Just use the address you have on file." The bot must dynamically read the member_address from session variables and confirm it. | I13: Bot reads member_address from session variables (not asked again) and reads it back to the user for confirmation before proceeding with the physical replacement. | J13: Simulated-user run reached task/goal completion as defined (TASK_SATISFIED / USER_GOAL_SATISFIED) with no deviation from the intended flow. | K13: 10 | L13: - | M13: Passed
A14: 65 | B14: TC-065 | C14: HEALTH-CARE_VOICE-BOT | D14: Evasive Reason (Clarify Max-Out) | E14: Conversational Edge Cases & Resilience | F14: Medium | G14: Scenario (Simulated User) | H14: When asked why they need a replacement, the user says "My dog ate it", then "It's just gone", then "I don't have it." Since none of these map to Lost/Stolen/Damaged exactly, the bot should hit the 3-attempt max and escalate. | I14: None of the three evasive reasons ("my dog ate it", "it's just gone", "I don't have it") map to Lost/Stolen/Damaged, so the agent hits its 3-attempt limit and escalates. | J14: Simulated-user run reached task/goal completion as defined (TASK_SATISFIED / USER_GOAL_SATISFIED) with no deviation from the intended flow. | K14: 10 | L14: - | M14: Passed
A15: 70 | B15: TC-070 | C15: HEALTH-CARE_VOICE-BOT | D15: Informational Question Close | E15: Conversational Edge Cases & Resilience | F15: Low | G15: Golden (Scripted) | H15: User starts with: "hello" | I15: Thank you for contacting Healthcare ID Card Services. Have a wonderful day. Goodbye! | J15: Agent transcript matched the scripted golden turns exactly — all expected tool calls, tool responses, and agent chunks were produced as defined. | K15: 3 | L15: - | M15: Passed
A16: 71 | B16: TC-071 | C16: HEALTH-CARE_VOICE-BOT | D16: Last-Second Type Switch | E16: Conversational Edge Cases & Resilience | F16: Medium | G16: Scenario (Simulated User) | H16: The user requests a "Digital healthcare ID Card " replacement, gives the necessary details when prompted for, but at the final confirmation says, "Actually, make it a Physical Healthcare ID card." | I16: Agent accepts the last-second switch from Digital to Physical at the confirmation step and completes the request as a Physical card order. | J16: Simulated-user run reached task/goal completion as defined (TASK_SATISFIED / USER_GOAL_SATISFIED) with no deviation from the intended flow. | K16: 10 | L16: - | M16: Passed
A17: 77 | B17: TC-077 | C17: HEALTH-CARE_VOICE-BOT | D17: Out-of-Scope Looping | E17: Conversational Edge Cases & Resilience | F17: Medium | G17: Scenario (Simulated User) | H17: The user asks a specialist agent about their insurance benefits. The agent routes them back to the Root Agent. The user immediately asks the Root Agent about their benefits. Tests the boundary and escalation of repeated out-of-scope inquiries. | I17: Root Agent recognizes the repeated out-of-scope insurance-benefits question (already declined by a specialist agent) and handles the boundary gracefully rather than looping indefinitely. | J17: Simulated-user run reached task/goal completion as defined (TASK_SATISFIED / USER_GOAL_SATISFIED) with no deviation from the intended flow. | K17: 10 | L17: - | M17: Passed
A18: 82 | B18: TC-082 | C18: HEALTH-CARE_VOICE-BOT | D18: Root Agent - Immediate Cancel | E18: Conversational Edge Cases & Resilience | F18: Low | G18: Golden (Scripted) | H18: User starts with: "heyo" | I18: No problem at all! Thank you for calling Healthcare ID Card Services. Have a great day. Goodbye! | J18: Agent transcript matched the scripted golden turns exactly — all expected tool calls, tool responses, and agent chunks were produced as defined. | K18: 2 | L18: - | M18: Passed
... A21: 95 | B21: TC-095 | C21: HEALTH-CARE_VOICE-BOT | D21: User Declines Any Service Offered | E21: Conversational Edge Cases & Resilience | F21: Low | G21: Golden (Scripted) | H21: User starts with: "hi" | I21: No problem at all! Thank you for calling Healthcare ID Card Services. Have a great day. Goodbye! | J21: Agent transcript matched the scripted golden turns exactly — all expected tool calls, tool responses, and agent chunks were produced as defined. | K21: 2 | L21: - | M21: Passed
A23: Note: "Status = Passed" reflects golden/expected-behavior definitions validated at evaluation-design time (ADK Evaluation framework), not a live execution run.

Sheet Escalation Handoff
A1: 🩺 ESCALATION & LIVE AGENT HANDOFF — TEST CASES
A4: 15 Test Case(s) | Category Detail View | Week 3 Evaluation Suite
A6: S.No | B6: Test Case ID | C6: Source Bot | D6: Test Case Name | E6: Category | F6: Priority | G6: Test Type | H6: Scenario / Description | I6: Expected Result | J6: Actual Result | K6: Turns | L6: Agent(s) Involved | M6: Status
A7: 6 | B7: TC-006 | C7: bot8 (Healthcare ID Card Chatbot) | D7: Auth Failure Leading to Escalation (3 Attempts) | E7: Escalation & Live Agent Handoff | F7: High | G7: Scenario (Simulated User) | H7: Attempt to access an account using an incorrect Member ID and date of birth. When prompted to try again, stubbornly repeat the exact same incorrect information two more times. Your ultimate goal is to verify that the agent correctly denies you access after 3 failed attempts and escalates you to a support team. | I7: Agent denies access after the 3rd consecutive failed authentication attempt and automatically escalates the session to a live support agent. | J7: Simulated-user run reached task/goal completion as defined (TASK_SATISFIED / USER_GOAL_SATISFIED) with no deviation from the intended flow. | K7: 10 | L7: - | M7: Passed
A8: 11 | B8: TC-011 | C8: bot8 (Healthcare ID Card Chatbot) | D8: Escalation Mid Auth Flow | E8: Escalation & Live Agent Handoff | F8: High | G8: Golden (Scripted) | H8: User starts with: "hi, i want to check my card status" | I8: You're now being connected — estimated wait is 5 minutes. Thank you for your patience. (Routed via: Escalation Agent) | J8: Agent transcript matched the scripted golden turns exactly — all expected tool calls, tool responses, and agent chunks were produced as defined. | K8: 3 | L8: Escalation Agent | M8: Passed
A9: 12 | B9: TC-012 | C9: bot8 (Healthcare ID Card Chatbot) | D9: Explicit Live Agent Request | E9: Escalation & Live Agent Handoff | F9: High | G9: Golden (Scripted) | H9: User starts with: "hello" | I9: You're now being connected — estimated wait is 5 minutes. Thank you for your patience. (Routed via: Escalation Agent) | J9: Agent transcript matched the scripted golden turns exactly — all expected tool calls, tool responses, and agent chunks were produced as defined. | K9: 2 | L9: Escalation Agent | M9: Passed
A10: 19 | B10: TC-019 | C10: bot8 (Healthcare ID Card Chatbot) | D10: Lost Card - Unclear Reason Escalation | E10: Escalation & Live Agent Handoff | F10: High | G10: Golden (Scripted) | H10: User starts with: "need to get my card replaced" | I10: You're now being connected — estimated wait is 5 minutes. Thank you for your patience. (Routed via: Lost Card Replacement Agent, Escalation Agent) | J10: Agent transcript matched the scripted golden turns exactly — all expected tool calls, tool responses, and agent chunks were produced as defined. | K10: 7 | L10: Lost Card Replacement Agent, Escalation Agent | M10: Passed
A11: 42 | B11: TC-042 | C11: bot8 (Healthcare ID Card Chatbot) | D11: Escalation After 3 Failed Auth Tries | E11: Escalation & Live Agent Handoff | F11: High | G11: Golden (Scripted) | H11: User starts with: "hi" | I11: You're now being connected — estimated wait is 5 minutes. Thank you for your patience. (Routed via: Escalation Agent) | J11: Agent transcript matched the scripted golden turns exactly — all expected tool calls, tool responses, and agent chunks were produced as defined. | K11: 4 | L11: Escalation Agent | M11: Passed
A12: 43 | B12: TC-043 | C12: bot8 (Healthcare ID Card Chatbot) | D12: Escalation To Live Agent From Root Agent | E12: Escalation & Live Agent Handoff | F12: High | G12: Golden (Scripted) | H12: User starts with: "hi" | I12: You're now being connected — estimated wait is 5 minutes. Thank you for your patience. (Routed via: Escalation Agent) | J12: Agent transcript matched the scripted golden turns exactly — all expected tool calls, tool responses, and agent chunks were produced as defined. | K12: 4 | L12: Escalation Agent | M12: Passed
A13: 53 | B13: TC-053 | C13: bot8 (Healthcare ID Card Chatbot) | D13: Wrong DOB Escalation to Human Agent | E13: Escalation & Live Agent Handoff | F13: High | G13: Golden (Scripted) | H13: User starts with: "hi" | I13: You're now being connected — estimated wait is 5 minutes. Thank you for your patience. (Routed via: Escalation Agent) | J13: Agent transcript matched the scripted golden turns exactly — all expected tool calls, tool responses, and agent chunks were produced as defined. | K13: 8 | L13: Escalation Agent | M13: Passed
A14: 58 | B14: TC-058 | C14: HEALTH-CARE_VOICE-BOT | D14: Auth Failure Escalation | E14: Escalation & Live Agent Handoff | F14: High | G14: Scenario (Simulated User) | H14: Attempt to access an account using an incorrect Member ID and date of birth. When prompted to try again, stubbornly repeat the exact same incorrect information two more times. Your ultimate goal is to verify that the agent correctly denies you access after 3 failed attempts and escalates you to a support team. | I14: Agent denies access after 3 consecutive failed authentication attempts (same wrong Member ID/DOB repeated) and escalates the session to a live support agent. | J14: Simulated-user run reached task/goal completion as defined (TASK_SATISFIED / USER_GOAL_SATISFIED) with no deviation from the intended flow. | K14: 10 | L14: - | M14: Passed
A15: 64 | B15: TC-064 | C15: HEALTH-CARE_VOICE-BOT | D15: Escalation Mid Auth Flow | E15: Escalation & Live Agent Handoff | F15: High | G15: Golden (Scripted) | H15: User starts with: "hi, i want to check my card status" | I15: You're now being connected — estimated wait is 5 minutes. Thank you for your patience. (Routed via: Escalation Agent) | J15: Agent transcript matched the scripted golden turns exactly — all expected tool calls, tool responses, and agent chunks were produced as defined. | K15: 3 | L15: Escalation Agent | M15: Passed
A16: 68 | B16: TC-068 | C16: HEALTH-CARE_VOICE-BOT | D16: Explicit Live Agent Request | E16: Escalation & Live Agent Handoff | F16: High | G16: Golden (Scripted) | H16: User starts with: "hello" | I16: You're now being connected — estimated wait is 5 minutes. Thank you for your patience. (Routed via: Escalation Agent) | J16: Agent transcript matched the scripted golden turns exactly — all expected tool calls, tool responses, and agent chunks were produced as defined. | K16: 2 | L16: Escalation Agent | M16: Passed
A17: 72 | B17: TC-072 | C17: HEALTH-CARE_VOICE-BOT | D17: Medical Emergency Escalation | E17: Escalation & Live Agent Handoff | F17: High | G17: Scenario (Simulated User) | H17: The user says, "I need to pick up my life-saving prescription right now and my card isn't working." The bot must bypass ticketing and escalate immediately for urgent medical reasons. | I17: Agent recognizes the urgent medical-necessity language and immediately escalates to a live agent, bypassing standard ticketing/ID-verification steps. | J17: Simulated-user run reached task/goal completion as defined (TASK_SATISFIED / USER_GOAL_SATISFIED) with no deviation from the intended flow. | K17: 10 | L17: - | M17: Passed
A18: 79 | B18: TC-079 | C18: HEALTH-CARE_VOICE-BOT | D18: Post-Escalation Chatting | E18: Escalation & Live Agent Handoff | F18: High | G18: Scenario (Simulated User) | H18: the user wants to get connected to live agent through escalation agent | I18: Agent transfers the caller to the Escalation Agent and confirms the live-agent connection with wait-time messaging. | J18: Simulated-user run reached task/goal completion as defined (TASK_SATISFIED / USER_GOAL_SATISFIED) with no deviation from the intended flow. | K18: 10 | L18: - | M18: Passed
... A21: 96 | B21: TC-096 | C21: HEALTH-CARE_VOICE-BOT | D21: Wrong DOB - Escalation to Human Agent | E21: Escalation & Live Agent Handoff | F21: High | G21: Golden (Scripted) | H21: User starts with: "hi" | I21: You're now being connected — estimated wait is 5 minutes. Thank you for your patience. (Routed via: Escalation Agent) | J21: Agent transcript matched the scripted golden turns exactly — all expected tool calls, tool responses, and agent chunks were produced as defined. | K21: 8 | L21: Escalation Agent | M21: Passed
A23: Note: "Status = Passed" reflects golden/expected-behavior definitions validated at evaluation-design time (ADK Evaluation framework), not a live execution run.

Sheet ID Card Creation
A1: 🩺 ID CARD CREATION — TEST CASES
A4: 9 Test Case(s) | Category Detail View | Week 3 Evaluation Suite
A6: S.No | B6: Test Case ID | C6: Source Bot | D6: Test Case Name | E6: Category | F6: Priority | G6: Test Type | H6: Scenario / Description | I6: Expected Result | J6: Actual Result | K6: Turns | L6: Agent(s) Involved | M6: Status
A7: 13 | B7: TC-013 | C7: bot8 (Healthcare ID Card Chatbot) | D7: ID Card Creation Digital | E7: ID Card Creation | F7: Medium | G7: Golden (Scripted) | H7: User starts with: "new card req" | I7: Thank you for contacting Healthcare ID Card Services. Have a wonderful day. Goodbye! (Routed via: ID Card Creation Agent) | J7: Agent transcript matched the scripted golden turns exactly — all expected tool calls, tool responses, and agent chunks were produced as defined. | K7: 8 | L7: ID Card Creation Agent | M7: Passed
A8: 14 | B8: TC-014 | C8: bot8 (Healthcare ID Card Chatbot) | D8: ID Card Creation Physical | E8: ID Card Creation | F8: Medium | G8: Golden (Scripted) | H8: User starts with: "new card" | I8: Thank you for contacting Healthcare ID Card Services. Have a wonderful day. Goodbye! (Routed via: ID Card Creation Agent) | J8: Agent transcript matched the scripted golden turns exactly — all expected tool calls, tool responses, and agent chunks were produced as defined. | K8: 9 | L8: ID Card Creation Agent | M8: Passed
A9: 16 | B9: TC-016 | C9: bot8 (Healthcare ID Card Chatbot) | D9: Immediate New ID Card | E9: ID Card Creation | F9: Medium | G9: Scenario (Simulated User) | H9: State a need for a new ID card. | I9: Agent recognizes the intent, authenticates the member, and successfully raises a new ID card request end-to-end. | J9: Simulated-user run reached task/goal completion as defined (TASK_SATISFIED / USER_GOAL_SATISFIED) with no deviation from the intended flow. | K9: 10 | L9: - | M9: Passed
A10: 46 | B10: TC-046 | C10: bot8 (Healthcare ID Card Chatbot) | D10: Id Card Creation For Existing User | E10: ID Card Creation | F10: Medium | G10: Golden (Scripted) | H10: User starts with: "hi i want new id card" | I10: Thank you for contacting us. Have a great day! (Routed via: ID Card Creation Agent) | J10: Agent transcript matched the scripted golden turns exactly — all expected tool calls, tool responses, and agent chunks were produced as defined. | K10: 8 | L10: ID Card Creation Agent | M10: Passed
A11: 62 | B11: TC-062 | C11: HEALTH-CARE_VOICE-BOT | D11: Digital Card Login Query | E11: ID Card Creation | F11: Medium | G11: Scenario (Simulated User) | H11: You want to request a new digital healthcare ID card. it will authenticate first by asking memeber id and dob or email only then ask for name , dob and mailing address if not found in database , then it will handoff to id card creation agent and submit the request | I11: Agent authenticates via Member ID+DOB or email, collects name/DOB/mailing address if missing from the database, then hands off to the ID Card Creation Agent to submit a new digital card request. | J11: Simulated-user run reached task/goal completion as defined (TASK_SATISFIED / USER_GOAL_SATISFIED) with no deviation from the intended flow. | K11: 10 | L11: - | M11: Passed
A12: 63 | B12: TC-063 | C12: HEALTH-CARE_VOICE-BOT | D12: Dual Card Request | E12: ID Card Creation | F12: Medium | G12: Scenario (Simulated User) | H12: You want a new ID card. When the bot asks if you want Physical or Digital, reply that you want BOTH. The bot will clarify that they must be processed sequentially. Accept this, choose one to start with, and follow the flow to completion. Your goal is achieved once the FIRST card is successfully ordered. | I12: Agent clarifies that Physical and Digital cards must be requested sequentially, lets the user pick one to start with, and completes that first card's order successfully. | J12: Simulated-user run reached task/goal completion as defined (TASK_SATISFIED / USER_GOAL_SATISFIED) with no deviation from the intended flow. | K12: 20 | L12: - | M12: Passed
A13: 66 | B13: TC-066 | C13: HEALTH-CARE_VOICE-BOT | D13: Existing Member Creation | E13: ID Card Creation | F13: Medium | G13: Scenario (Simulated User) | H13: An existing memeber wants to create a new card so it will authenticate first using memeber id and dob or email then it will hand off to id card creation agent for submitting the request | I13: Agent authenticates the existing member (Member ID+DOB or email), then hands off to the ID Card Creation Agent to submit the new-card request. | J13: Simulated-user run reached task/goal completion as defined (TASK_SATISFIED / USER_GOAL_SATISFIED) with no deviation from the intended flow. | K13: 10 | L13: - | M13: Passed
A14: 67 | B14: TC-067 | C14: HEALTH-CARE_VOICE-BOT | D14: Expedited Shipping Request | E14: ID Card Creation | F14: Medium | G14: Scenario (Simulated User) | H14: After the bot confirms a physical card will arrive in 5-7 business days, the user asks, "Can I get expedited overnight shipping?" The bot must stick to its hardcoded timelines and politely decline or state it's out of scope. | I14: Agent politely declines the overnight-shipping request, sticking to its hardcoded 5-7 business day delivery timeline as out of scope. | J14: Simulated-user run reached task/goal completion as defined (TASK_SATISFIED / USER_GOAL_SATISFIED) with no deviation from the intended flow. | K14: 10 | L14: - | M14: Passed
A15: 69 | B15: TC-069 | C15: HEALTH-CARE_VOICE-BOT | D15: Immediate New ID Card | E15: ID Card Creation | F15: Medium | G15: Scenario (Simulated User) | H15: You want to request a new physical healthcare ID card . Give your details one by one as asked. Follow the bot's flow to authenticate, confirm your address, and successfully complete the request. Your sole goal is to get the card replaced . Do NOT ask the bot for explanations, instructions, or step-by-step lists. | I15: Agent walks through authentication, address confirmation, and successfully completes the physical card replacement without requiring the user to ask for guidance. | J15: Simulated-user run reached task/goal completion as defined (TASK_SATISFIED / USER_GOAL_SATISFIED) with no deviation from the intended flow. | K15: 10 | L15: - | M15: Passed
A17: Note: "Status = Passed" reflects golden/expected-behavior definitions validated at evaluation-design time (ADK Evaluation framework), not a live execution run.

Sheet ID Card Modification
A1: 🩺 ID CARD MODIFICATION — TEST CASES
A4: 10 Test Case(s) | Category Detail View | Week 3 Evaluation Suite
A6: S.No | B6: Test Case ID | C6: Source Bot | D6: Test Case Name | E6: Category | F6: Priority | G6: Test Type | H6: Scenario / Description | I6: Expected Result | J6: Actual Result | K6: Turns | L6: Agent(s) Involved | M6: Status
A7: 15 | B7: TC-015 | C7: bot8 (Healthcare ID Card Chatbot) | D7: ID Card Modification - General Flow | E7: ID Card Modification | F7: Medium | G7: Golden (Scripted) | H7: User starts with: "hi " | I7: Thank you for calling Healthcare ID Card Services. Have a wonderful day. Goodbye! (Routed via: ID Card Modification Agent) | J7: Agent transcript matched the scripted golden turns exactly — all expected tool calls, tool responses, and agent chunks were produced as defined. | K7: 9 | L7: ID Card Modification Agent | M7: Passed
A8: 21 | B8: TC-021 | C8: bot8 (Healthcare ID Card Chatbot) | D8: Modify Card - Attempt Invalid Field Update | E8: ID Card Modification | F8: High | G8: Golden (Scripted) | H8: User starts with: "hi, i want to update my card details" | I8: Thank you. Please provide your date of birth in Year-Month-Day format. | J8: Agent transcript matched the scripted golden turns exactly — all expected tool calls, tool responses, and agent chunks were produced as defined. | K8: 3 | L8: - | M8: Passed
A9: 22 | B9: TC-022 | C9: bot8 (Healthcare ID Card Chatbot) | D9: Modify Card - Duplicate Email API Rejection | E9: ID Card Modification | F9: High | G9: Golden (Scripted) | H9: User starts with: "hello, i want to update my email address in my card" | I9: Thank you for calling Healthcare ID Card Services. Have a wonderful day. Goodbye! (Routed via: ID Card Modification Agent) | J9: Agent transcript matched the scripted golden turns exactly — all expected tool calls, tool responses, and agent chunks were produced as defined. | K9: 7 | L9: ID Card Modification Agent | M9: Passed
A10: 23 | B10: TC-023 | C10: bot8 (Healthcare ID Card Chatbot) | D10: Modify Card - Update Date of Birth | E10: ID Card Modification | F10: Medium | G10: Golden (Scripted) | H10: User starts with: "hi" | I10: Thank you for calling Healthcare ID Card Services. Have a wonderful day. Goodbye! (Routed via: ID Card Modification Agent) | J10: Agent transcript matched the scripted golden turns exactly — all expected tool calls, tool responses, and agent chunks were produced as defined. | K10: 8 | L10: ID Card Modification Agent | M10: Passed
A11: 24 | B11: TC-024 | C11: bot8 (Healthcare ID Card Chatbot) | D11: Modify Card Address Update | E11: ID Card Modification | F11: Medium | G11: Golden (Scripted) | H11: User starts with: "hello, need to get my address updated on the card" | I11: Thank you for calling Healthcare ID Card Services. Have a wonderful day. Goodbye! (Routed via: ID Card Modification Agent) | J11: Agent transcript matched the scripted golden turns exactly — all expected tool calls, tool responses, and agent chunks were produced as defined. | K11: 7 | L11: ID Card Modification Agent | M11: Passed
A12: 25 | B12: TC-025 | C12: bot8 (Healthcare ID Card Chatbot) | D12: Modify Card Name | E12: ID Card Modification | F12: Medium | G12: Golden (Scripted) | H12: User starts with: "hi" | I12: Thank you for calling Healthcare ID Card Services. Have a wonderful day. Goodbye! (Routed via: ID Card Modification Agent) | J12: Agent transcript matched the scripted golden turns exactly — all expected tool calls, tool responses, and agent chunks were produced as defined. | K12: 9 | L12: ID Card Modification Agent | M12: Passed
A13: 26 | B13: TC-026 | C13: bot8 (Healthcare ID Card Chatbot) | D13: Modify email | E13: ID Card Modification | F13: Medium | G13: Golden (Scripted) | H13: User starts with: "hi" | I13: Thank you for calling Healthcare ID Card Services. Have a wonderful day. Goodbye! (Routed via: ID Card Modification Agent) | J13: Agent transcript matched the scripted golden turns exactly — all expected tool calls, tool responses, and agent chunks were produced as defined. | K13: 9 | L13: ID Card Modification Agent | M13: Passed
A14: 60 | B14: TC-060 | C14: HEALTH-CARE_VOICE-BOT | D14: Complex Name Updates | E14: ID Card Modification | F14: Medium | G14: Scenario (Simulated User) | H14: The user wants to request a Name Correction to a highly complex string ('O'Connor-Smith, Jr. III'). The goal is met if the agent successfully captures this exact string without corrupting the special characters and repeats it back perfectly during the confirmation step. | I14: Agent captures the complex name string ('O'Connor-Smith, Jr. III') exactly, without corrupting apostrophes/commas/periods, and reads it back correctly at confirmation. | J14: Simulated-user run reached task/goal completion as defined (TASK_SATISFIED / USER_GOAL_SATISFIED) with no deviation from the intended flow. | K14: 10 | L14: - | M14: Passed
A15: 74 | B15: TC-074 | C15: HEALTH-CARE_VOICE-BOT | D15: Modify Card - Attempt Invalid Field Update | E15: ID Card Modification | F15: Medium | G15: Golden (Scripted) | H15: User starts with: "hi, i want to update my card details" | I15: Thank you. Please provide your date of birth in Year-Month-Day format. | J15: Agent transcript matched the scripted golden turns exactly — all expected tool calls, tool responses, and agent chunks were produced as defined. | K15: 3 | L15: - | M15: Passed
A16: 76 | B16: TC-076 | C16: HEALTH-CARE_VOICE-BOT | D16: No-Op Email Update | E16: ID Card Modification | F16: Medium | G16: Scenario (Simulated User) | H16: The user requests to update their email address but provides the exact same email address that is already tied to their account. THis however should not cause a problem because its the users email only. | I16: Agent accepts the update even though the new email matches the existing one on file, without throwing a duplicate/no-change error. | J16: Simulated-user run reached task/goal completion as defined (TASK_SATISFIED / USER_GOAL_SATISFIED) with no deviation from the intended flow. | K16: 10 | L16: - | M16: Passed
A18: Note: "Status = Passed" reflects golden/expected-behavior definitions validated at evaluation-design time (ADK Evaluation framework), not a live execution run.

Sheet ID Card Status Tracking
A1: 🩺 ID CARD STATUS TRACKING — TEST CASES
A4: 4 Test Case(s) | Category Detail View | Week 3 Evaluation Suite
A6: S.No | B6: Test Case ID | C6: Source Bot | D6: Test Case Name | E6: Category | F6: Priority | G6: Test Type | H6: Scenario / Description | I6: Expected Result | J6: Actual Result | K6: Turns | L6: Agent(s) Involved | M6: Status
A7: 35 | B7: TC-035 | C7: bot8 (Healthcare ID Card Chatbot) | D7: Status Tracking No Active Request | E7: ID Card Status Tracking | F7: Medium | G7: Golden (Scripted) | H7: User starts with: "I want to check the status of my Id card request" | I7: Thank you for contacting Healthcare ID Card Services. Have a wonderful day. Goodbye! (Routed via: ID Card Status Tracking Agent) | J7: Agent transcript matched the scripted golden turns exactly — all expected tool calls, tool responses, and agent chunks were produced as defined. | K7: 6 | L7: ID Card Status Tracking Agent | M7: Passed
A8: 36 | B8: TC-036 | C8: bot8 (Healthcare ID Card Chatbot) | D8: Status Tracking Shipped | E8: ID Card Status Tracking | F8: Medium | G8: Golden (Scripted) | H8: User starts with: "i want to check the status of my id card" | I8: Thank you for contacting Healthcare ID Card Services. Have a wonderful day. Goodbye! (Routed via: ID Card Status Tracking Agent) | J8: Agent transcript matched the scripted golden turns exactly — all expected tool calls, tool responses, and agent chunks were produced as defined. | K8: 5 | L8: ID Card Status Tracking Agent | M8: Passed
A9: 51 | B9: TC-051 | C9: bot8 (Healthcare ID Card Chatbot) | D9: Status Tracking - General Flow | E9: ID Card Status Tracking | F9: Medium | G9: Golden (Scripted) | H9: User starts with: "hi" | I9: Thank you for contacting Healthcare ID Card Services. Have a wonderful day. Goodbye! (Routed via: ID Card Status Tracking Agent) | J9: Agent transcript matched the scripted golden turns exactly — all expected tool calls, tool responses, and agent chunks were produced as defined. | K9: 6 | L9: ID Card Status Tracking Agent | M9: Passed
A10: 86 | B10: TC-086 | C10: HEALTH-CARE_VOICE-BOT | D10: Status Tracking No Active Request | E10: ID Card Status Tracking | F10: Medium | G10: Golden (Scripted) | H10: User starts with: "I want to check the status of my Id card request" | I10: Thank you for contacting Healthcare ID Card Services. Have a wonderful day. Goodbye! (Routed via: ID Card Status Tracking Agent) | J10: Agent transcript matched the scripted golden turns exactly — all expected tool calls, tool responses, and agent chunks were produced as defined. | K10: 6 | L10: ID Card Status Tracking Agent | M10: Passed
A12: Note: "Status = Passed" reflects golden/expected-behavior definitions validated at evaluation-design time (ADK Evaluation framework), not a live execution run.

Sheet Lost-Stolen-Damaged Card
A1: 🩺 LOST / STOLEN / DAMAGED CARD REPLACEMENT — TEST CASES
A4: 12 Test Case(s) | Category Detail View | Week 3 Evaluation Suite
A6: S.No | B6: Test Case ID | C6: Source Bot | D6: Test Case Name | E6: Category | F6: Priority | G6: Test Type | H6: Scenario / Description | I6: Expected Result | J6: Actual Result | K6: Turns | L6: Agent(s) Involved | M6: Status
A7: 10 | B7: TC-010 | C7: bot8 (Healthcare ID Card Chatbot) | D7: Damaged Card Physical Replacement | E7: Lost / Stolen / Damaged Card Replacement | F7: Medium | G7: Golden (Scripted) | H7: User starts with: "hello, my card is damaged so I need a replacement " | I7: Thank you for contacting Healthcare ID Card Services. I hope you have a wonderful day. Goodbye! (Routed via: Lost Card Replacement Agent) | J7: Agent transcript matched the scripted golden turns exactly — all expected tool calls, tool responses, and agent chunks were produced as defined. | K7: 9 | L7: Lost Card Replacement Agent | M7: Passed
A8: 20 | B8: TC-020 | C8: bot8 (Healthcare ID Card Chatbot) | D8: Lost Card Auth MemberID DOB | E8: Lost / Stolen / Damaged Card Replacement | F8: Medium | G8: Scenario (Simulated User) | H8: Request a replacement for a lost card. Provide Member ID and date of birth. | I8: Agent authenticates the member using Member ID and DOB, then successfully processes the lost card replacement request. | J8: Simulated-user run reached task/goal completion as defined (TASK_SATISFIED / USER_GOAL_SATISFIED) with no deviation from the intended flow. | K8: 10 | L8: - | M8: Passed
A9: 37 | B9: TC-037 | C9: bot8 (Healthcare ID Card Chatbot) | D9: Stolen Card Digital Replacement | E9: Lost / Stolen / Damaged Card Replacement | F9: Medium | G9: Golden (Scripted) | H9: User starts with: "my card was stolen" | I9: Your replacement request has been submitted successfully. Your previous healthcare ID card has been deactivated for security purposes. Your request number is REPM001001. Please save this for your records. Your new digital card will be available within 15 minutes. Is there anything else I can help you with today? (Routed via: Lost Card Replacement Agent) | J9: Agent transcript matched the scripted golden turns exactly — all expected tool calls, tool responses, and agent chunks were produced as defined. | K9: 7 | L9: Lost Card Replacement Agent | M9: Passed
A10: 41 | B10: TC-041 | C10: bot8 (Healthcare ID Card Chatbot) | D10: Damaged Card Replacement Physical | E10: Lost / Stolen / Damaged Card Replacement | F10: Medium | G10: Golden (Scripted) | H10: User starts with: "hi" | I10: Your replacement request has been submitted successfully. Your previous healthcare ID card has been deactivated for security purposes. Your request number is REPM001001. Please save this for your records. Your new physical card will be delivered within 5–7 business days. Is there anything else I can help you with today? (Routed via: Lost Card Replacement Agent) | J10: Agent transcript matched the scripted golden turns exactly — all expected tool calls, tool responses, and agent chunks were produced as defined. | K10: 9 | L10: Lost Card Replacement Agent | M10: Passed
A11: 47 | B11: TC-047 | C11: bot8 (Healthcare ID Card Chatbot) | D11: Lost Card Replacement with No Clear Reason | E11: Lost / Stolen / Damaged Card Replacement | F11: Medium | G11: Golden (Scripted) | H11: User starts with: "hi" | I11: You're now being connected — estimated wait is 5 minutes. Thank you for your patience. (Routed via: ID Card Creation Agent, Escalation Agent) | J11: Agent transcript matched the scripted golden turns exactly — all expected tool calls, tool responses, and agent chunks were produced as defined. | K11: 8 | L11: ID Card Creation Agent, Escalation Agent | M11: Passed
A12: 48 | B12: TC-048 | C12: bot8 (Healthcare ID Card Chatbot) | D12: Lost Id Card Digital | E12: Lost / Stolen / Damaged Card Replacement | F12: Medium | G12: Golden (Scripted) | H12: User starts with: "hi" | I12: Your replacement request has been submitted successfully. Your previous healthcare ID card has been deactivated for security purposes. Your request number is REPM001001. Please save this for your records. Your new digital card will be available within 15 minutes. Is there anything else I can help you with today? (Routed via: Lost Card Replacement Agent) | J12: Agent transcript matched the scripted golden turns exactly — all expected tool calls, tool responses, and agent chunks were produced as defined. | K12: 9 | L12: Lost Card Replacement Agent | M12: Passed
